Workbook

Sheet Raw_Data
A1: Order_ID | B1: Order_Date | C1: Customer_Name | D1: Product | E1: Category | F1: Region | G1: Quantity | H1: Sales | I1: Discount | J1: Profit
A2: Order_ID | B2: Order_Date | C2: Customer_Name | D2: Product | E2: Category | F2: Region | G2: Quantity | H2: Sales | I2: Discount | J2: Profit
A3: ORD0001 | B3: 46094 | C3: Karthik | D3: Desk Lamp | E3: Home | F3: Central | G3: 1 | H3: 1620 | I3: 10 | J3: 160.68
A4: ORD0002 | B4: 46134 | C4: Rahul | D4: Smartphone | E4: Electronics | F4: Central | G4: 2 | H4: 56000 | I4: 0 | J4: 3626.98
A5: ORD0003 | B5: 46382 | C5: Dinesh | D5: Watch | E5: Accessories | F5: West | G5: 1 | H5: 4275 | I5: 5 | J5: 746.26
A6: ORD0004 | B6: 46026 | C6: Vijay | D6: Keyboard | E6: Electronics | F6: West | G6: 1 | H6: 2700 | I6: 10 | J6: 511.67
A7: ORD0005 | B7: 46195 | C7: Karthik | D7: Office Chair | E7: Furniture | F7: South | G7: 1 | H7: 8075 | I7: 5 | J7: 1721.22
A8: ORD0006 | B8: 46045 | C8: Keerthi | D8: Study Table | E8: Furniture | F8: Central | G8: 1 | H8: 10800 | I8: 10 | J8: 1691.24
A9: ORD0007 | B9: 46173 | C9: Pooja | D9: Smartphone | E9: Electronics | F9: East | G9: 5 | H9: 119000 | I9: 15 | J9: 8640.36
A10: ORD0008 | B10: 46139 | C10: Suresh | D10: Watch | E10: Accessories | F10: South | G10: 1 | H10: 4500 | I10: 0 | J10: 302.99
A11: ORD0009 | B11: 46348 | C11: Ajay | D11: Keyboard | E11: Electronics | F11: North | G11: 3 | H11: 7650 | I11: 15 | J11: 799.24
A12: ORD0010 | B12: 46372 | C12: Priya | D12: Office Chair | E12: Furniture | F12: Central | G12: 1 | H12: 7650 | I12: 10 | J12: 1318.03
A13: ORD0011 | B13: 46217 | C13: Sneha | D13: Desk Lamp | E13: Home | F13: Central | G13: 1 | H13: 1710 | I13: 5 | J13: 147.31
A14: ORD0012 | B14: 46039 | C14: Meena | D14: Keyboard | E14: Electronics | F14: West | G14: 2 | H14: 6000 | I14: 0 | J14: 579.89
... A502: ORD0500 | B502: 46104 | C502: Karthik | D502: Bookshelf | E502: Furniture | F502: North | G502: 2 | H502: 11200 | I502: 20 | J502: 2463.29

Sheet Cleaned_Data
A1: Order_ID | B1: Order_Date | C1: Customer_Name | D1: Product | E1: Category | F1: Region | G1: Quantity | H1: Sales | I1: Discount | J1: Profit | K1: Month
A2: ORD0001 | B2: 46094 | C2: Karthik | D2: Desk Lamp | E2: Home | F2: Central | G2: 1 | H2: 1620 | I2: 10 | J2: 160.68 | K2: =TEXT(B2,"mmm") -> Mar
A3: ORD0002 | B3: 46134 | C3: Rahul | D3: Smartphone | E3: Electronics | F3: Central | G3: 2 | H3: 56000 | I3: 0 | J3: 3626.98 | K3: =TEXT(B3,"mmm") -> Apr
A4: ORD0003 | B4: 46382 | C4: Dinesh | D4: Watch | E4: Accessories | F4: West | G4: 1 | H4: 4275 | I4: 5 | J4: 746.26 | K4: =TEXT(B4,"mmm") -> Dec
A5: ORD0004 | B5: 46026 | C5: Vijay | D5: Keyboard | E5: Electronics | F5: West | G5: 1 | H5: 2700 | I5: 10 | J5: 511.67 | K5: =TEXT(B5,"mmm") -> Jan
A6: ORD0005 | B6: 46195 | C6: Karthik | D6: Office Chair | E6: Furniture | F6: South | G6: 1 | H6: 8075 | I6: 5 | J6: 1721.22 | K6: =TEXT(B6,"mmm") -> Jun
A7: ORD0006 | B7: 46045 | C7: Keerthi | D7: Study Table | E7: Furniture | F7: Central | G7: 1 | H7: 10800 | I7: 10 | J7: 1691.24 | K7: =TEXT(B7,"mmm") -> Jan
A8: ORD0007 | B8: 46173 | C8: Pooja | D8: Smartphone | E8: Electronics | F8: East | G8: 5 | H8: 119000 | I8: 15 | J8: 8640.36 | K8: =TEXT(B8,"mmm") -> May
A9: ORD0008 | B9: 46139 | C9: Suresh | D9: Watch | E9: Accessories | F9: South | G9: 1 | H9: 4500 | I9: 0 | J9: 302.99 | K9: =TEXT(B9,"mmm") -> Apr
A10: ORD0009 | B10: 46348 | C10: Ajay | D10: Keyboard | E10: Electronics | F10: North | G10: 3 | H10: 7650 | I10: 15 | J10: 799.24 | K10: =TEXT(B10,"mmm") -> Nov
A11: ORD0010 | B11: 46372 | C11: Priya | D11: Office Chair | E11: Furniture | F11: Central | G11: 1 | H11: 7650 | I11: 10 | J11: 1318.03 | K11: =TEXT(B11,"mmm") -> Dec
A12: ORD0011 | B12: 46217 | C12: Sneha | D12: Desk Lamp | E12: Home | F12: Central | G12: 1 | H12: 1710 | I12: 5 | J12: 147.31 | K12: =TEXT(B12,"mmm") -> Jul
A13: ORD0012 | B13: 46039 | C13: Meena | D13: Keyboard | E13: Electronics | F13: West | G13: 2 | H13: 6000 | I13: 0 | J13: 579.89 | K13: =TEXT(B13,"mmm") -> Jan
... A501: ORD0500 | B501: 46104 | C501: Karthik | D501: Bookshelf | E501: Furniture | F501: North | G501: 2 | H501: 11200 | I501: 20 | J501: 2463.29 | K501: =TEXT(B501,"mmm") -> Mar

Sheet Analysis
A1: E-Commerce Sales Analysis
A3: Total Sales | B3: =SUM(Cleaned_Data!H2:H501) -> 9248905
A4: Total Profit | B4: =SUM(Cleaned_Data!J2:J501) -> 1302212.2
A5: Total Orders | B5: =COUNTA(SalesData[Order_ID ]) -> 500
A6: Total Quantity | B6: =SUM(SalesData[[ Quantity ]]) -> 961
A7: Average Order Value | B7: =B3/B5 -> 18497.81
A10: Category | B10: Total Sales
A11: Accessories | B11: 453530
A12: Electronics | B12: 6732300
A13: Furniture | B13: 1856300
A14: Home | B14: 206775
A15: Grand Total | B15: 9248905
A20: Region | B20: Total Sales
A21: Central | B21: 2250675
A22: East | B22: 1393310
A23: North | B23: 1761585
A24: South | B24: 2068360
A25: West | B25: 1774975
A26: Grand Total | B26: 9248905
A30: Product | B30: Total Sales
A31: Laptop | B31: 3938000
A32: Smartphone | B32: 2220400
A33: Study Table | B33: 794400
A34: Bookshelf | B34: 585900
A35: Office Chair | B35: 476000
A36: Grand Total | B36: 8014700
A51: Month | B51: Total sales
A52: Jan | B52: 596335
A53: Feb | B53: 706050
A54: Mar | B54: 712525
A55: Apr | B55: 868575
A56: May | B56: 880745
A57: Jun | B57: 892245
A58: Jul | B58: 734720
A59: Aug | B59: 1083230
A60: Sep | B60: 770840
A61: Oct | B61: 757245
A62: Nov | B62: 670965
A63: Dec | B63: 575430
A64: Grand Total | B64: 9248905
...

Sheet Dashboard
A1: E-Commerce Sales Dashboard
A4: Total Sales | C4: Total Profit | E4: Total Orders | G4: Average Order Value
A5: =Analysis!B3 -> 9248905 | C5: =Analysis!B4 -> 1302212.2 | E5: =Analysis!B5 -> 500 | G5: =Analysis!B7 -> 18497.81
